Workbook

Sheet 人员名单
A2: 编号 | B2: 姓名 | C2: 单位 | D2: 职务 | E2: 座位号
A3: 1 | B3: 王祺扬 | D3: 海南省委常委、三亚市委书记 | E3: 第一排1号
A4: 2 | B4: 孙 键 | C4: 中国科技部国际合作司 | D4: 副司长 | E4: 第一排2号
A5: 3 | B5: 张永涛 | C5: 中国21世纪议程管理中心 | D5: 副主任 | E5: 第一排3号
A6: 4 | B6: FARID CHEMALE JUNlOR 法里德·谢马莱·朱尼尔 | C6: 巴西大洋钻探联盟 | D6: 主席/院士 | E6: 第一排4号
A7: 5 | B7: 谢 京 | C7: 海南省人民政府 | D7: 副省长 | E7: 第一排5号
A8: 6 | B8: 刘西宁 | C8: 广州海洋地质调查局 | D8: 三亚所海洋测绘研究室主任 | E8: 第一排20号
A9: 7 | B9: 杨 刚 | C9: 国际基础地理信息中心 | D9: 博士 | E9: 第二排15号
A10: 8 | B10: 唐 享 | C10: 广州海洋地质调查局 | D10: 高级工程师 | E10: 第三排2号

Sheet 座位图 
Q1: 场地座位分布图
A2: ●红色区域为沙发区
B3: 数量：4+7+4=15
Q4: 舞台
A5: ●左侧可容纳117人
A6: ●中间可容纳214人
A7: ●右侧可容纳117人 | G7: 1
A8: 合计：448人
I13: 13 | K13: 11 | M13: 9 | S13: 7 | U13: 5 | W13: 3 | Y13: 1 | AA13: 2 | AC13: 4 | AE13: 6 | AK13: 8 | AM13: 10 | AO13: 12 | AW13: 沙发区 | AY13: 13
I15: =_xlfn.XLOOKUP(I13,人员名单!$E:$E,人员名单!$B:$B) -> #N/A | K15: =_xlfn.XLOOKUP(K13,人员名单!$E:$E,人员名单!$B:$B) -> #N/A | M15: =_xlfn.XLOOKUP(M13,人员名单!$E:$E,人员名单!$B:$B) -> #N/A | S15: =_xlfn.XLOOKUP(S13,人员名单!$E:$E,人员名单!$B:$B) -> #N/A | U15: =_xlfn.XLOOKUP(U13,人员名单!$E:$E,人员名单!$B:$B) -> #N/A | W15: =_xlfn.XLOOKUP(W13,人员名单!$E:$E,人员名单!$B:$B) -> #N/A | Y15: =_xlfn.XLOOKUP(Y13,人员名单!$E:$E,人员名单!$B:$B) -> #N/A | AA15: =_xlfn.XLOOKUP(AA13,人员名单!$E:$E,人员名单!$B:$B) -> #N/A | AC15: =_xlfn.XLOOKUP(AC13,人员名单!$E:$E,人员名单!$B:$B) -> #N/A | AE15: =_xlfn.XLOOKUP(AE13,人员名单!$E:$E,人员名单!$B:$B) -> #N/A | AK15: =_xlfn.XLOOKUP(AK13,人员名单!$E:$E,人员名单!$B:$B) -> #N/A | AM15: =_xlfn.XLOOKUP(AM13,人员名单!$E:$E,人员名单!$B:$B) -> #N/A | AO15: =_xlfn.XLOOKUP(AO13,人员名单!$E:$E,人员名单!$B:$B) -> #N/A
A17: 第1排 | F17: 37 | G17: 36 | H17: 35 | I17: 34 | J17: 33 | K17: 32 | L17: 31 | M17: 30 | N17: 29 | Q17: 28 | R17: 27 | S17: 26 | T17: 25 | U17: 24 | V17: 23 | W17: 22 | X17: 21 | Y17: 20 | Z17: 19 | AA17: 18 | AB17: 17 | AC17: 16 | AD17: 15 | AE17: 14 | AF17: 13 | AG17: 12 | AJ17: 11 | AK17: 10 | AL17: 9 | AM17: 8 | AN17: 7 | AO17: 6 | AP17: 5 | AQ17: 4 | AR17: 3 | AW17: 第1排 | AY17: 35
F18: 48 | G18: 46 | H18: 44 | I18: 42 | J18: 40 | K18: 38 | L18: 36 | M18: 34 | N18: 32 | Q18: 30 | R18: 28 | S18: 26 | T18: 24 | U18: 22 | V18: 20 | W18: 18 | X18: 16 | Y18: 14 | Z18: 15 | AA18: 17 | AB18: 19 | AC18: 21 | AD18: 23 | AE18: 25 | AF18: 27 | AG18: 29 | AJ18: 31 | AK18: 33 | AL18: 35 | AM18: 37 | AN18: 39 | AO18: 41 | AP18: 43 | AQ18: 45 | AR18: 47
F19: =_xlfn.XLOOKUP(F18,人员名单!$E:$E,人员名单!$B:$B) -> #N/A | G19: =_xlfn.XLOOKUP(G18,人员名单!$E:$E,人员名单!$B:$B) -> #N/A | H19: =_xlfn.XLOOKUP(H18,人员名单!$E:$E,人员名单!$B:$B) -> #N/A | I19: =_xlfn.XLOOKUP(I18,人员名单!$E:$E,人员名单!$B:$B) -> #N/A | J19: =_xlfn.XLOOKUP(J18,人员名单!$E:$E,人员名单!$B:$B) -> #N/A | K19: =_xlfn.XLOOKUP(K18,人员名单!$E:$E,人员名单!$B:$B) -> #N/A | L19: =_xlfn.XLOOKUP(L18,人员名单!$E:$E,人员名单!$B:$B) -> #N/A | M19: =_xlfn.XLOOKUP(M18,人员名单!$E:$E,人员名单!$B:$B) -> #N/A | N19: =_xlfn.XLOOKUP(N18,人员名单!$E:$E,人员名单!$B:$B) -> #N/A | Q19: =_xlfn.XLOOKUP(Q18,人员名单!$E:$E,人员名单!$B:$B) -> #N/A | R19: =_xlfn.XLOOKUP(R18,人员名单!$E:$E,人员名单!$B:$B) -> #N/A | S19: =_xlfn.XLOOKUP(S18,人员名单!$E:$E,人员名单!$B:$B) -> #N/A | T19: =_xlfn.XLOOKUP(T18,人员名单!$E:$E,人员名单!$B:$B) -> #N/A | U19: =_xlfn.XLOOKUP(U18,人员名单!$E:$E,人员名单!$B:$B) -> #N/A | V19: =_xlfn.XLOOKUP(V18,人员名单!$E:$E,人员名单!$B:$B) -> #N/A | W19: =_xlfn.XLOOKUP(W18,人员名单!$E:$E,人员名单!$B:$B) -> #N/A | X19: =_xlfn.XLOOKUP(X18,人员名单!$E:$E,人员名单!$B:$B) -> #N/A | ... AG19: =_xlfn.XLOOKUP(AG18,人员名单!$E:$E,人员名单!$B:$B) -> #N/A | AJ19: =_xlfn.XLOOKUP(AJ18,人员名单!$E:$E,人员名单!$B:$B) -> #N/A | AK19: =_xlfn.XLOOKUP(AK18,人员名单!$E:$E,人员名单!$B:$B) -> #N/A | AL19: =_xlfn.XLOOKUP(AL18,人员名单!$E:$E,人员名单!$B:$B) -> #N/A | AM19: =_xlfn.XLOOKUP(AM18,人员名单!$E:$E,人员名单!$B:$B) -> #N/A | AN19: =_xlfn.XLOOKUP(AN18,人员名单!$E:$E,人员名单!$B:$B) -> #N/A | AO19: =_xlfn.XLOOKUP(AO18,人员名单!$E:$E,人员名单!$B:$B) -> #N/A | AP19: =_xlfn.XLOOKUP(AP18,人员名单!$E:$E,人员名单!$B:$B) -> #N/A | AQ19: =_xlfn.XLOOKUP(AQ18,人员名单!$E:$E,人员名单!$B:$B) -> #N/A | AR19: =_xlfn.XLOOKUP(AR18,人员名单!$E:$E,人员名单!$B:$B) -> #N/A
A21: 第2排 | E21: 41 | F21: 40 | G21: 39 | H21: 38 | I21: 37 | J21: 36 | K21: 35 | L21: 34 | M21: 33 | N21: 32 | P21: 31 | Q21: 30 | R21: 29 | S21: 28 | T21: 27 | U21: 26 | V21: 25 | W21: 24 | X21: 23 | Y21: 22 | Z21: 21 | AA21: 20 | AB21: 19 | AC21: 18 | AD21: 17 | AE21: 16 | AF21: 15 | AG21: 14 | AH21: 13 | AJ21: 12 | AK21: 11 | AL21: 10 | AM21: 9 | AN21: 8 | AO21: 7 | AP21: 6 | AQ21: 5 | AR21: 4 | AS21: 3 | AW21: 第2排 | AY21: 39
E22: 87 | F22: 85 | G22: 83 | H22: 81 | I22: 79 | J22: 77 | K22: 75 | L22: 73 | M22: 71 | N22: 69 | P22: 67 | Q22: 65 | R22: 63 | S22: 61 | T22: 59 | U22: 57 | V22: 55 | W22: 53 | X22: 51 | Y22: 49 | Z22: 50 | AA22: 52 | AB22: 54 | AC22: 56 | AD22: 58 | AE22: 60 | AF22: 62 | AG22: 64 | AH22: 66 | AJ22: 68 | AK22: 70 | AL22: 72 | AM22: 74 | AN22: 76 | AO22: 78 | AP22: 80 | AQ22: 82 | AR22: 84 | AS22: 86
E23: =_xlfn.XLOOKUP(E22,人员名单!$E:$E,人员名单!$B:$B) -> #N/A | F23: =_xlfn.XLOOKUP(F22,人员名单!$E:$E,人员名单!$B:$B) -> #N/A | G23: =_xlfn.XLOOKUP(G22,人员名单!$E:$E,人员名单!$B:$B) -> #N/A | H23: =_xlfn.XLOOKUP(H22,人员名单!$E:$E,人员名单!$B:$B) -> #N/A | I23: =_xlfn.XLOOKUP(I22,人员名单!$E:$E,人员名单!$B:$B) -> #N/A | J23: =_xlfn.XLOOKUP(J22,人员名单!$E:$E,人员名单!$B:$B) -> #N/A | K23: =_xlfn.XLOOKUP(K22,人员名单!$E:$E,人员名单!$B:$B) -> #N/A | L23: =_xlfn.XLOOKUP(L22,人员名单!$E:$E,人员名单!$B:$B) -> #N/A | ... N23: =_xlfn.XLOOKUP(N22,人员名单!$E:$E,人员名单!$B:$B) -> #N/A | P23: =_xlfn.XLOOKUP(P22,人员名单!$E:$E,人员名单!$B:$B) -> #N/A | Q23: =_xlfn.XLOOKUP(Q22,人员名单!$E:$E,人员名单!$B:$B) -> #N/A | R23: =_xlfn.XLOOKUP(R22,人员名单!$E:$E,人员名单!$B:$B) -> #N/A | S23: =_xlfn.XLOOKUP(S22,人员名单!$E:$E,人员名单!$B:$B) -> #N/A | T23: =_xlfn.XLOOKUP(T22,人员名单!$E:$E,人员名单!$B:$B) -> #N/A | U23: =_xlfn.XLOOKUP(U22,人员名单!$E:$E,人员名单!$B:$B) -> #N/A | V23: =_xlfn.XLOOKUP(V22,人员名单!$E:$E,人员名单!$B:$B) -> #N/A | W23: =_xlfn.XLOOKUP(W22,人员名单!$E:$E,人员名单!$B:$B) -> #N/A | ... AH23: =_xlfn.XLOOKUP(AH22,人员名单!$E:$E,人员名单!$B:$B) -> #N/A | AJ23: =_xlfn.XLOOKUP(AJ22,人员名单!$E:$E,人员名单!$B:$B) -> #N/A | AK23: =_xlfn.XLOOKUP(AK22,人员名单!$E:$E,人员名单!$B:$B) -> #N/A | AL23: =_xlfn.XLOOKUP(AL22,人员名单!$E:$E,人员名单!$B:$B) -> #N/A | AM23: =_xlfn.XLOOKUP(AM22,人员名单!$E:$E,人员名单!$B:$B) -> #N/A | AN23: =_xlfn.XLOOKUP(AN22,人员名单!$E:$E,人员名单!$B:$B) -> #N/A | AO23: =_xlfn.XLOOKUP(AO22,人员名单!$E:$E,人员名单!$B:$B) -> #N/A | AP23: =_xlfn.XLOOKUP(AP22,人员名单!$E:$E,人员名单!$B:$B) -> #N/A | AQ23: =_xlfn.XLOOKUP(AQ22,人员名单!$E:$E,人员名单!$B:$B) -> #N/A | ... AS23: =_xlfn.XLOOKUP(AS22,人员名单!$E:$E,人员名单!$B:$B) -> #N/A
A25: 第3排 | D25: 42 | E25: 41 | F25: 40 | G25: 39 | H25: 38 | I25: 37 | J25: 36 | K25: 35 | L25: 34 | M25: 33 | N25: 32 | P25: 31 | Q25: 30 | R25: 29 | S25: 28 | T25: 27 | U25: 26 | V25: 25 | W25: 24 | X25: 23 | Y25: 22 | Z25: 21 | AA25: 20 | AB25: 19 | AC25: 18 | AD25: 17 | AE25: 16 | AF25: 15 | AG25: 14 | AH25: 13 | AJ25: 12 | AK25: 11 | AL25: 10 | AM25: 9 | AN25: 8 | AO25: 7 | AP25: 6 | AQ25: 5 | AR25: 4 | AS25: 3 | AT25: 2 | AW25: 第3排 | AY25: 41
D26: 128 | E26: 126 | F26: 124 | G26: 122 | H26: 120 | I26: 118 | J26: 116 | K26: 114 | L26: 112 | M26: 110 | N26: 108 | P26: 106 | Q26: 104 | R26: 102 | S26: 100 | T26: 98 | U26: 96 | V26: 94 | W26: 92 | X26: 90 | Y26: 88 | Z26: 89 | AA26: 91 | AB26: 93 | AC26: 95 | AD26: 97 | AE26: 99 | AF26: 101 | AG26: 103 | AH26: 105 | AJ26: 107 | AK26: 109 | AL26: 111 | AM26: 113 | AN26: 115 | AO26: 117 | AP26: 119 | AQ26: 121 | AR26: 123 | AS26: 125 | AT26: 127
D27: =_xlfn.XLOOKUP(D26,人员名单!$E:$E,人员名单!$B:$B) -> #N/A | E27: =_xlfn.XLOOKUP(E26,人员名单!$E:$E,人员名单!$B:$B) -> #N/A | F27: =_xlfn.XLOOKUP(F26,人员名单!$E:$E,人员名单!$B:$B) -> #N/A | G27: =_xlfn.XLOOKUP(G26,人员名单!$E:$E,人员名单!$B:$B) -> #N/A | H27: =_xlfn.XLOOKUP(H26,人员名单!$E:$E,人员名单!$B:$B) -> #N/A | I27: =_xlfn.XLOOKUP(I26,人员名单!$E:$E,人员名单!$B:$B) -> #N/A | J27: =_xlfn.XLOOKUP(J26,人员名单!$E:$E,人员名单!$B:$B) -> #N/A | K27: =_xlfn.XLOOKUP(K26,人员名单!$E:$E,人员名单!$B:$B) -> #N/A | ... N27: =_xlfn.XLOOKUP(N26,人员名单!$E:$E,人员名单!$B:$B) -> #N/A | P27: =_xlfn.XLOOKUP(P26,人员名单!$E:$E,人员名单!$B:$B) -> #N/A | Q27: =_xlfn.XLOOKUP(Q26,人员名单!$E:$E,人员名单!$B:$B) -> #N/A | R27: =_xlfn.XLOOKUP(R26,人员名单!$E:$E,人员名单!$B:$B) -> #N/A | S27: =_xlfn.XLOOKUP(S26,人员名单!$E:$E,人员名单!$B:$B) -> #N/A | T27: =_xlfn.XLOOKUP(T26,人员名单!$E:$E,人员名单!$B:$B) -> #N/A | U27: =_xlfn.XLOOKUP(U26,人员名单!$E:$E,人员名单!$B:$B) -> #N/A | V27: =_xlfn.XLOOKUP(V26,人员名单!$E:$E,人员名单!$B:$B) -> #N/A | W27: =_xlfn.XLOOKUP(W26,人员名单!$E:$E,人员名单!$B:$B) -> #N/A | ... AH27: =_xlfn.XLOOKUP(AH26,人员名单!$E:$E,人员名单!$B:$B) -> #N/A | AJ27: =_xlfn.XLOOKUP(AJ26,人员名单!$E:$E,人员名单!$B:$B) -> #N/A | AK27: =_xlfn.XLOOKUP(AK26,人员名单!$E:$E,人员名单!$B:$B) -> #N/A | AL27: =_xlfn.XLOOKUP(AL26,人员名单!$E:$E,人员名单!$B:$B) -> #N/A | AM27: =_xlfn.XLOOKUP(AM26,人员名单!$E:$E,人员名单!$B:$B) -> #N/A | AN27: =_xlfn.XLOOKUP(AN26,人员名单!$E:$E,人员名单!$B:$B) -> #N/A | AO27: =_xlfn.XLOOKUP(AO26,人员名单!$E:$E,人员名单!$B:$B) -> #N/A | AP27: =_xlfn.XLOOKUP(AP26,人员名单!$E:$E,人员名单!$B:$B) -> #N/A | AQ27: =_xlfn.XLOOKUP(AQ26,人员名单!$E:$E,人员名单!$B:$B) -> #N/A | ... AT27: =_xlfn.XLOOKUP(AT26,人员名单!$E:$E,人员名单!$B:$B) -> #N/A
A29: 第4排 | D29: 42 | E29: 41 | F29: 40 | G29: 39 | H29: 38 | I29: 37 | J29: 36 | K29: 35 | L29: 34 | M29: 33 | N29: 32 | P29: 31 | Q29: 30 | R29: 29 | S29: 28 | T29: 27 | U29: 26 | V29: 25 | W29: 24 | X29: 23 | Y29: 22 | Z29: 21 | AA29: 20 | AB29: 19 | AC29: 18 | AD29: 17 | AE29: 16 | AF29: 15 | AG29: 14 | AH29: 13 | AJ29: 12 | AK29: 11 | AL29: 10 | AM29: 9 | AN29: 8 | AO29: 7 | AP29: 6 | AQ29: 5 | AR29: 4 | AS29: 3 | AT29: 2 | AW29: 第4排 | AY29: 41
D30: 169 | E30: 167 | F30: 165 | G30: 163 | H30: 161 | I30: 159 | J30: 157 | K30: 155 | L30: 153 | M30: 151 | N30: 149 | P30: 147 | Q30: 145 | R30: 143 | S30: 141 | T30: 139 | U30: 137 | V30: 135 | W30: 133 | X30: 131 | Y30: 129 | Z30: 130 | AA30: 132 | AB30: 134 | AC30: 136 | AD30: 138 | AE30: 140 | AF30: 142 | AG30: 144 | AH30: 146 | AJ30: 148 | AK30: 150 | AL30: 152 | AM30: 154 | AN30: 156 | AO30: 158 | AP30: 160 | AQ30: 162 | AR30: 164 | AS30: 166 | AT30: 168
D31: =_xlfn.XLOOKUP(D30,人员名单!$E:$E,人员名单!$B:$B) -> #N/A | E31: =_xlfn.XLOOKUP(E30,人员名单!$E:$E,人员名单!$B:$B) -> #N/A | F31: =_xlfn.XLOOKUP(F30,人员名单!$E:$E,人员名单!$B:$B) -> #N/A | G31: =_xlfn.XLOOKUP(G30,人员名单!$E:$E,人员名单!$B:$B) -> #N/A | H31: =_xlfn.XLOOKUP(H30,人员名单!$E:$E,人员名单!$B:$B) -> #N/A | I31: =_xlfn.XLOOKUP(I30,人员名单!$E:$E,人员名单!$B:$B) -> #N/A | J31: =_xlfn.XLOOKUP(J30,人员名单!$E:$E,人员名单!$B:$B) -> #N/A | K31: =_xlfn.XLOOKUP(K30,人员名单!$E:$E,人员名单!$B:$B) -> #N/A | ... N31: =_xlfn.XLOOKUP(N30,人员名单!$E:$E,人员名单!$B:$B) -> #N/A | P31: =_xlfn.XLOOKUP(P30,人员名单!$E:$E,人员名单!$B:$B) -> #N/A | Q31: =_xlfn.XLOOKUP(Q30,人员名单!$E:$E,人员名单!$B:$B) -> #N/A | R31: =_xlfn.XLOOKUP(R30,人员名单!$E:$E,人员名单!$B:$B) -> #N/A | S31: =_xlfn.XLOOKUP(S30,人员名单!$E:$E,人员名单!$B:$B) -> #N/A | T31: =_xlfn.XLOOKUP(T30,人员名单!$E:$E,人员名单!$B:$B) -> #N/A | U31: =_xlfn.XLOOKUP(U30,人员名单!$E:$E,人员名单!$B:$B) -> #N/A | V31: =_xlfn.XLOOKUP(V30,人员名单!$E:$E,人员名单!$B:$B) -> #N/A | W31: =_xlfn.XLOOKUP(W30,人员名单!$E:$E,人员名单!$B:$B) -> #N/A | ... AH31: =_xlfn.XLOOKUP(AH30,人员名单!$E:$E,人员名单!$B:$B) -> #N/A | AJ31: =_xlfn.XLOOKUP(AJ30,人员名单!$E:$E,人员名单!$B:$B) -> #N/A | AK31: =_xlfn.XLOOKUP(AK30,人员名单!$E:$E,人员名单!$B:$B) -> #N/A | AL31: =_xlfn.XLOOKUP(AL30,人员名单!$E:$E,人员名单!$B:$B) -> #N/A | AM31: =_xlfn.XLOOKUP(AM30,人员名单!$E:$E,人员名单!$B:$B) -> #N/A | AN31: =_xlfn.XLOOKUP(AN30,人员名单!$E:$E,人员名单!$B:$B) -> #N/A | AO31: =_xlfn.XLOOKUP(AO30,人员名单!$E:$E,人员名单!$B:$B) -> #N/A | AP31: =_xlfn.XLOOKUP(AP30,人员名单!$E:$E,人员名单!$B:$B) -> #N/A | AQ31: =_xlfn.XLOOKUP(AQ30,人员名单!$E:$E,人员名单!$B:$B) -> #N/A | ... AT31: =_xlfn.XLOOKUP(AT30,人员名单!$E:$E,人员名单!$B:$B) -> #N/A
D32: 付 | N32: 费 | AJ32: 付 | AT32: 费
A33: 第5排 | C33: 44 | D33: 43 | E33: 42 | F33: 41 | G33: 40 | H33: 39 | I33: 38 | J33: 37 | K33: 36 | L33: 35 | M33: 34 | N33: 33 | P33: 32 | Q33: 31 | R33: 30 | S33: 29 | T33: 28 | U33: 27 | V33: 26 | W33: 25 | X33: 24 | Y33: 23 | Z33: 22 | AA33: 21 | AB33: 20 | AC33: 19 | AD33: 18 | AE33: 17 | AF33: 16 | AG33: 15 | AH33: 14 | AJ33: 13 | AK33: 12 | AL33: 11 | AM33: 10 | AN33: 9 | AO33: 8 | AP33: 7 | AQ33: 6 | AR33: 5 | AS33: 4 | AT33: 3 | AU33: 2 | AW33: 第5排 | AY33: 43
C34: 212 | D34: 210 | E34: 208 | F34: 206 | G34: 204 | H34: 202 | I34: 200 | J34: 198 | K34: 196 | L34: 194 | M34: 192 | N34: 190 | P34: 188 | Q34: 186 | R34: 184 | S34: 182 | T34: 180 | U34: 178 | V34: 176 | W34: 174 | X34: 172 | Y34: 170 | Z34: 171 | AA34: 173 | AB34: 175 | AC34: 177 | AD34: 179 | AE34: 181 | AF34: 183 | AG34: 185 | AH34: 187 | AJ34: 189 | AK34: 191 | AL34: 193 | AM34: 195 | AN34: 197 | AO34: 199 | AP34: 201 | AQ34: 203 | AR34: 205 | AS34: 207 | AT34: 209 | AU34: 211
C35: =_xlfn.XLOOKUP(C34,人员名单!$E:$E,人员名单!$B:$B) -> #N/A | D35: =_xlfn.XLOOKUP(D34,人员名单!$E:$E,人员名单!$B:$B) -> #N/A | E35: =_xlfn.XLOOKUP(E34,人员名单!$E:$E,人员名单!$B:$B) -> #N/A | F35: =_xlfn.XLOOKUP(F34,人员名单!$E:$E,人员名单!$B:$B) -> #N/A | G35: =_xlfn.XLOOKUP(G34,人员名单!$E:$E,人员名单!$B:$B) -> #N/A | H35: =_xlfn.XLOOKUP(H34,人员名单!$E:$E,人员名单!$B:$B) -> #N/A | I35: =_xlfn.XLOOKUP(I34,人员名单!$E:$E,人员名单!$B:$B) -> #N/A | J35: =_xlfn.XLOOKUP(J34,人员名单!$E:$E,人员名单!$B:$B) -> #N/A | ... N35: =_xlfn.XLOOKUP(N34,人员名单!$E:$E,人员名单!$B:$B) -> #N/A | P35: =_xlfn.XLOOKUP(P34,人员名单!$E:$E,人员名单!$B:$B) -> #N/A | Q35: =_xlfn.XLOOKUP(Q34,人员名单!$E:$E,人员名单!$B:$B) -> #N/A | R35: =_xlfn.XLOOKUP(R34,人员名单!$E:$E,人员名单!$B:$B) -> #N/A | S35: =_xlfn.XLOOKUP(S34,人员名单!$E:$E,人员名单!$B:$B) -> #N/A | T35: =_xlfn.XLOOKUP(T34,人员名单!$E:$E,人员名单!$B:$B) -> #N/A | U35: =_xlfn.XLOOKUP(U34,人员名单!$E:$E,人员名单!$B:$B) -> #N/A | V35: =_xlfn.XLOOKUP(V34,人员名单!$E:$E,人员名单!$B:$B) -> #N/A | W35: =_xlfn.XLOOKUP(W34,人员名单!$E:$E,人员名单!$B:$B) -> #N/A | ... AH35: =_xlfn.XLOOKUP(AH34,人员名单!$E:$E,人员名单!$B:$B) -> #N/A | AJ35: =_xlfn.XLOOKUP(AJ34,人员名单!$E:$E,人员名单!$B:$B) -> #N/A | AK35: =_xlfn.XLOOKUP(AK34,人员名单!$E:$E,人员名单!$B:$B) -> #N/A | AL35: =_xlfn.XLOOKUP(AL34,人员名单!$E:$E,人员名单!$B:$B) -> #N/A | AM35: =_xlfn.XLOOKUP(AM34,人员名单!$E:$E,人员名单!$B:$B) -> #N/A | AN35: =_xlfn.XLOOKUP(AN34,人员名单!$E:$E,人员名单!$B:$B) -> #N/A | AO35: =_xlfn.XLOOKUP(AO34,人员名单!$E:$E,人员名单!$B:$B) -> #N/A | AP35: =_xlfn.XLOOKUP(AP34,人员名单!$E:$E,人员名单!$B:$B) -> #N/A | AQ35: =_xlfn.XLOOKUP(AQ34,人员名单!$E:$E,人员名单!$B:$B) -> #N/A | ... AU35: =_xlfn.XLOOKUP(AU34,人员名单!$E:$E,人员名单!$B:$B) -> #N/A
A37: 第6排 | D37: 42 | E37: 41 | F37: 40 | G37: 39 | H37: 38 | I37: 37 | J37: 36 | K37: 35 | L37: 34 | M37: 33 | N37: 32 | P37: 31 | Q37: 30 | R37: 29 | S37: 28 | T37: 27 | U37: 26 | V37: 25 | W37: 24 | X37: 23 | Y37: 22 | Z37: 21 | AA37: 20 | AB37: 19 | AC37: 18 | AD37: 17 | AE37: 16 | AF37: 15 | AG37: 14 | AH37: 13 | AJ37: 12 | AK37: 11 | AL37: 10 | AM37: 9 | AN37: 8 | AO37: 7 | AP37: 6 | AQ37: 5 | AR37: 4 | AS37: 3 | AT37: 2 | AW37: 第6排 | AY37: 41
D38: 253 | E38: 251 | F38: 249 | G38: 247 | H38: 245 | I38: 243 | J38: 241 | K38: 239 | L38: 237 | M38: 235 | N38: 233 | P38: 231 | Q38: 229 | R38: 227 | S38: 225 | T38: 223 | U38: 221 | V38: 219 | W38: 217 | X38: 215 | Y38: 213 | Z38: 214 | AA38: 216 | AB38: 218 | AC38: 220 | AD38: 222 | AE38: 224 | AF38: 226 | AG38: 228 | AH38: 230 | AJ38: 232 | AK38: 234 | AL38: 236 | AM38: 238 | AN38: 240 | AO38: 242 | AP38: 244 | AQ38: 246 | AR38: 248 | AS38: 250 | AT38: 252 | BA38: 30
D39: =_xlfn.XLOOKUP(D38,人员名单!$E:$E,人员名单!$B:$B) -> #N/A | E39: =_xlfn.XLOOKUP(E38,人员名单!$E:$E,人员名单!$B:$B) -> #N/A | F39: =_xlfn.XLOOKUP(F38,人员名单!$E:$E,人员名单!$B:$B) -> #N/A | G39: =_xlfn.XLOOKUP(G38,人员名单!$E:$E,人员名单!$B:$B) -> #N/A | H39: =_xlfn.XLOOKUP(H38,人员名单!$E:$E,人员名单!$B:$B) -> #N/A | I39: =_xlfn.XLOOKUP(I38,人员名单!$E:$E,人员名单!$B:$B) -> #N/A | J39: =_xlfn.XLOOKUP(J38,人员名单!$E:$E,人员名单!$B:$B) -> #N/A | K39: =_xlfn.XLOOKUP(K38,人员名单!$E:$E,人员名单!$B:$B) -> #N/A | ... N39: =_xlfn.XLOOKUP(N38,人员名单!$E:$E,人员名单!$B:$B) -> #N/A | P39: =_xlfn.XLOOKUP(P38,人员名单!$E:$E,人员名单!$B:$B) -> #N/A | Q39: =_xlfn.XLOOKUP(Q38,人员名单!$E:$E,人员名单!$B:$B) -> #N/A | R39: =_xlfn.XLOOKUP(R38,人员名单!$E:$E,人员名单!$B:$B) -> #N/A | S39: =_xlfn.XLOOKUP(S38,人员名单!$E:$E,人员名单!$B:$B) -> #N/A | T39: =_xlfn.XLOOKUP(T38,人员名单!$E:$E,人员名单!$B:$B) -> #N/A | U39: =_xlfn.XLOOKUP(U38,人员名单!$E:$E,人员名单!$B:$B) -> #N/A | V39: =_xlfn.XLOOKUP(V38,人员名单!$E:$E,人员名单!$B:$B) -> #N/A | W39: =_xlfn.XLOOKUP(W38,人员名单!$E:$E,人员名单!$B:$B) -> #N/A | ... AF39: =_xlfn.XLOOKUP(AF38,人员名单!$E:$E,人员名单!$B:$B) -> #N/A | AG39: =AE14$B:$B) | AH39: =_xlfn.XLOOKUP(AH38,人员名单!$E:$E,人员名单!$B:$B) -> #N/A | AJ39: =_xlfn.XLOOKUP(AJ38,人员名单!$E:$E,人员名单!$B:$B) -> #N/A | AK39: =_xlfn.XLOOKUP(AK38,人员名单!$E:$E,人员名单!$B:$B) -> #N/A | AL39: =_xlfn.XLOOKUP(AL38,人员名单!$E:$E,人员名单!$B:$B) -> #N/A | AM39: =_xlfn.XLOOKUP(AM38,人员名单!$E:$E,人员名单!$B:$B) -> #N/A | AN39: =_xlfn.XLOOKUP(AN38,人员名单!$E:$E,人员名单!$B:$B) -> #N/A | AO39: =_xlfn.XLOOKUP(AO38,人员名单!$E:$E,人员名单!$B:$B) -> #N/A | AP39: =_xlfn.XLOOKUP(AP38,人员名单!$E:$E,人员名单!$B:$B) -> #N/A | AQ39: =_xlfn.XLOOKUP(AQ38,人员名单!$E:$E,人员名单!$B:$B) -> #N/A | ... AT39: =_xlfn.XLOOKUP(AT38,人员名单!$E:$E,人员名单!$B:$B) -> #N/A
A41: 第7排 | D41: 42 | E41: 41 | F41: 40 | G41: 39 | H41: 38 | I41: 37 | J41: 36 | K41: 35 | L41: 34 | M41: 33 | N41: 32 | P41: 31 | Q41: 30 | R41: 29 | S41: 28 | T41: 27 | U41: 26 | V41: 25 | W41: 24 | X41: 23 | Y41: 22 | Z41: 21 | AA41: 20 | AB41: 19 | AC41: 18 | AD41: 17 | AE41: 16 | AF41: 15 | AG41: 14 | AH41: 13 | AJ41: 12 | AK41: 11 | AL41: 10 | AM41: 9 | AN41: 8 | AO41: 7 | AP41: 6 | AQ41: 5 | AR41: 4 | AS41: 3 | AT41: 2 | AW41: 第7排 | AY41: 41
D42: 294 | E42: 292 | F42: 290 | G42: 288 | H42: 286 | I42: 284 | J42: 282 | K42: 280 | L42: 278 | M42: 276 | N42: 274 | P42: 272 | Q42: 270 | R42: 268 | S42: 266 | T42: 264 | U42: 262 | V42: 260 | W42: 258 | X42: 256 | Y42: 254 | Z42: 255 | AA42: 257 | AB42: 259 | AC42: 261 | AD42: 263 | AE42: 265 | AF42: 267 | AG42: 269 | AH42: 271 | AJ42: 273 | AK42: 275 | AL42: 277 | AM42: 279 | AN42: 281 | AO42: 283 | AP42: 285 | AQ42: 287 | AR42: 289 | AS42: 291 | AT42: 293
D43: =_xlfn.XLOOKUP(D42,人员名单!$E:$E,人员名单!$B:$B) -> #N/A | E43: =_xlfn.XLOOKUP(E42,人员名单!$E:$E,人员名单!$B:$B) -> #N/A | F43: =_xlfn.XLOOKUP(F42,人员名单!$E:$E,人员名单!$B:$B) -> #N/A | G43: =_xlfn.XLOOKUP(G42,人员名单!$E:$E,人员名单!$B:$B) -> #N/A | H43: =_xlfn.XLOOKUP(H42,人员名单!$E:$E,人员名单!$B:$B) -> #N/A | I43: =_xlfn.XLOOKUP(I42,人员名单!$E:$E,人员名单!$B:$B) -> #N/A | J43: =_xlfn.XLOOKUP(J42,人员名单!$E:$E,人员名单!$B:$B) -> #N/A | K43: =_xlfn.XLOOKUP(K42,人员名单!$E:$E,人员名单!$B:$B) -> #N/A | ... N43: =_xlfn.XLOOKUP(N42,人员名单!$E:$E,人员名单!$B:$B) -> #N/A | P43: =_xlfn.XLOOKUP(P42,人员名单!$E:$E,人员名单!$B:$B) -> #N/A | Q43: =_xlfn.XLOOKUP(Q42,人员名单!$E:$E,人员名单!$B:$B) -> #N/A | R43: =_xlfn.XLOOKUP(R42,人员名单!$E:$E,人员名单!$B:$B) -> #N/A | S43: =_xlfn.XLOOKUP(S42,人员名单!$E:$E,人员名单!$B:$B) -> #N/A | T43: =_xlfn.XLOOKUP(T42,人员名单!$E:$E,人员名单!$B:$B) -> #N/A | U43: =_xlfn.XLOOKUP(U42,人员名单!$E:$E,人员名单!$B:$B) -> #N/A | V43: =_xlfn.XLOOKUP(V42,人员名单!$E:$E,人员名单!$B:$B) -> #N/A | W43: =_xlfn.XLOOKUP(W42,人员名单!$E:$E,人员名单!$B:$B) -> #N/A | ... AH43: =_xlfn.XLOOKUP(AH42,人员名单!$E:$E,人员名单!$B:$B) -> #N/A | AJ43: =_xlfn.XLOOKUP(AJ42,人员名单!$E:$E,人员名单!$B:$B) -> #N/A | AK43: =_xlfn.XLOOKUP(AK42,人员名单!$E:$E,人员名单!$B:$B) -> #N/A | AL43: =_xlfn.XLOOKUP(AL42,人员名单!$E:$E,人员名单!$B:$B) -> #N/A | AM43: =_xlfn.XLOOKUP(AM42,人员名单!$E:$E,人员名单!$B:$B) -> #N/A | AN43: =_xlfn.XLOOKUP(AN42,人员名单!$E:$E,人员名单!$B:$B) -> #N/A | AO43: =_xlfn.XLOOKUP(AO42,人员名单!$E:$E,人员名单!$B:$B) -> #N/A | AP43: =_xlfn.XLOOKUP(AP42,人员名单!$E:$E,人员名单!$B:$B) -> #N/A | AQ43: =_xlfn.XLOOKUP(AQ42,人员名单!$E:$E,人员名单!$B:$B) -> #N/A | ... AT43: =_xlfn.XLOOKUP(AT42,人员名单!$E:$E,人员名单!$B:$B) -> #N/A
A45: 第8排 | D45: 42 | E45: 41 | F45: 40 | G45: 39 | H45: 38 | I45: 37 | J45: 36 | K45: 35 | L45: 34 | M45: 33 | N45: 32 | P45: 31 | Q45: 30 | R45: 29 | S45: 28 | T45: 27 | U45: 26 | V45: 25 | W45: 24 | X45: 23 | Y45: 22 | Z45: 21 | AA45: 20 | AB45: 19 | AC45: 18 | AD45: 17 | AE45: 16 | AF45: 15 | AG45: 14 | AH45: 13 | AJ45: 12 | AK45: 11 | AL45: 10 | AM45: 9 | AN45: 8 | AO45: 7 | AP45: 6 | AQ45: 5 | AR45: 4 | AS45: 3 | AT45: 2 | AW45: 第8排 | AY45: 41
D46: 335 | E46: 333 | F46: 331 | G46: 329 | H46: 327 | I46: 325 | J46: 323 | K46: 321 | L46: 319 | M46: 317 | N46: 315 | P46: 313 | Q46: 311 | R46: 309 | S46: 307 | T46: 305 | U46: 303 | V46: 301 | W46: 299 | X46: 297 | Y46: 295 | Z46: 296 | AA46: 298 | AB46: 300 | AC46: 302 | AD46: 304 | AE46: 306 | AF46: 308 | AG46: 310 | AH46: 312 | AJ46: 314 | AK46: 316 | AL46: 318 | AM46: 320 | AN46: 322 | AO46: 324 | AP46: 326 | AQ46: 328 | AR46: 330 | AS46: 332 | AT46: 334
D47: =_xlfn.XLOOKUP(D46,人员名单!$E:$E,人员名单!$B:$B) -> #N/A | E47: =_xlfn.XLOOKUP(E46,人员名单!$E:$E,人员名单!$B:$B) -> #N/A | F47: =_xlfn.XLOOKUP(F46,人员名单!$E:$E,人员名单!$B:$B) -> #N/A | G47: =_xlfn.XLOOKUP(G46,人员名单!$E:$E,人员名单!$B:$B) -> #N/A | H47: =_xlfn.XLOOKUP(H46,人员名单!$E:$E,人员名单!$B:$B) -> #N/A | I47: =_xlfn.XLOOKUP(I46,人员名单!$E:$E,人员名单!$B:$B) -> #N/A | J47: =_xlfn.XLOOKUP(J46,人员名单!$E:$E,人员名单!$B:$B) -> #N/A | K47: =_xlfn.XLOOKUP(K46,人员名单!$E:$E,人员名单!$B:$B) -> #N/A | ... N47: =_xlfn.XLOOKUP(N46,人员名单!$E:$E,人员名单!$B:$B) -> #N/A | P47: =_xlfn.XLOOKUP(P46,人员名单!$E:$E,人员名单!$B:$B) -> #N/A | Q47: =_xlfn.XLOOKUP(Q46,人员名单!$E:$E,人员名单!$B:$B) -> #N/A | R47: =_xlfn.XLOOKUP(R46,人员名单!$E:$E,人员名单!$B:$B) -> #N/A | S47: =_xlfn.XLOOKUP(S46,人员名单!$E:$E,人员名单!$B:$B) -> #N/A | T47: =_xlfn.XLOOKUP(T46,人员名单!$E:$E,人员名单!$B:$B) -> #N/A | U47: =_xlfn.XLOOKUP(U46,人员名单!$E:$E,人员名单!$B:$B) -> #N/A | V47: =_xlfn.XLOOKUP(V46,人员名单!$E:$E,人员名单!$B:$B) -> #N/A | W47: =_xlfn.XLOOKUP(W46,人员名单!$E:$E,人员名单!$B:$B) -> #N/A | ... AH47: =_xlfn.XLOOKUP(AH46,人员名单!$E:$E,人员名单!$B:$B) -> #N/A | AJ47: =_xlfn.XLOOKUP(AJ46,人员名单!$E:$E,人员名单!$B:$B) -> #N/A | AK47: =_xlfn.XLOOKUP(AK46,人员名单!$E:$E,人员名单!$B:$B) -> #N/A | AL47: =_xlfn.XLOOKUP(AL46,人员名单!$E:$E,人员名单!$B:$B) -> #N/A | AM47: =_xlfn.XLOOKUP(AM46,人员名单!$E:$E,人员名单!$B:$B) -> #N/A | AN47: =_xlfn.XLOOKUP(AN46,人员名单!$E:$E,人员名单!$B:$B) -> #N/A | AO47: =_xlfn.XLOOKUP(AO46,人员名单!$E:$E,人员名单!$B:$B) -> #N/A | AP47: =_xlfn.XLOOKUP(AP46,人员名单!$E:$E,人员名单!$B:$B) -> #N/A | AQ47: =_xlfn.XLOOKUP(AQ46,人员名单!$E:$E,人员名单!$B:$B) -> #N/A | ... AT47: =_xlfn.XLOOKUP(AT46,人员名单!$E:$E,人员名单!$B:$B) -> #N/A
A49: 第9排 | E49: 38 | F49: 37 | G49: 36 | H49: 35 | I49: 34 | J49: 33 | K49: 32 | L49: 31 | M49: 30 | N49: 29 | Q49: 28 | R49: 27 | S49: 26 | T49: 25 | U49: 24 | V49: 23 | W49: 22 | X49: 21 | Y49: 20 | Z49: 19 | AA49: 18 | AB49: 17 | AC49: 16 | AD49: 15 | AE49: 14 | AF49: 13 | AG49: 12 | AJ49: 11 | AK49: 10 | AL49: 9 | AM49: 8 | AN49: 7 | AO49: 6 | AP49: 5 | AQ49: 4 | AR49: 3 | AS49: 2 | AW49: 第9排 | AY49: 37
E50: 372 | F50: 370 | G50: 368 | H50: 366 | I50: 364 | J50: 362 | K50: 360 | L50: 358 | M50: 356 | N50: 354 | Q50: 352 | R50: 350 | S50: 348 | T50: 346 | U50: 344 | V50: 342 | W50: 340 | X50: 338 | Y50: 336 | Z50: 337 | AA50: 339 | AB50: 341 | AC50: 343 | AD50: 345 | AE50: 347 | AF50: 349 | AG50: 351 | AJ50: 353 | AK50: 355 | AL50: 357 | AM50: 359 | AN50: 361 | AO50: 363 | AP50: 365 | AQ50: 367 | AR50: 369 | AS50: 371
E51: =_xlfn.XLOOKUP(E50,人员名单!$E:$E,人员名单!$B:$B) -> #N/A | F51: =_xlfn.XLOOKUP(F50,人员名单!$E:$E,人员名单!$B:$B) -> #N/A | G51: =_xlfn.XLOOKUP(G50,人员名单!$E:$E,人员名单!$B:$B) -> #N/A | H51: =_xlfn.XLOOKUP(H50,人员名单!$E:$E,人员名单!$B:$B) -> #N/A | I51: =_xlfn.XLOOKUP(I50,人员名单!$E:$E,人员名单!$B:$B) -> #N/A | J51: =_xlfn.XLOOKUP(J50,人员名单!$E:$E,人员名单!$B:$B) -> #N/A | K51: =_xlfn.XLOOKUP(K50,人员名单!$E:$E,人员名单!$B:$B) -> #N/A | L51: =_xlfn.XLOOKUP(L50,人员名单!$E:$E,人员名单!$B:$B) -> #N/A | ... N51: =_xlfn.XLOOKUP(N50,人员名单!$E:$E,人员名单!$B:$B) -> #N/A | Q51: =_xlfn.XLOOKUP(Q50,人员名单!$E:$E,人员名单!$B:$B) -> #N/A | R51: =_xlfn.XLOOKUP(R50,人员名单!$E:$E,人员名单!$B:$B) -> #N/A | S51: =_xlfn.XLOOKUP(S50,人员名单!$E:$E,人员名单!$B:$B) -> #N/A | T51: =_xlfn.XLOOKUP(T50,人员名单!$E:$E,人员名单!$B:$B) -> #N/A | U51: =_xlfn.XLOOKUP(U50,人员名单!$E:$E,人员名单!$B:$B) -> #N/A | V51: =_xlfn.XLOOKUP(V50,人员名单!$E:$E,人员名单!$B:$B) -> #N/A | W51: =_xlfn.XLOOKUP(W50,人员名单!$E:$E,人员名单!$B:$B) -> #N/A | X51: =_xlfn.XLOOKUP(X50,人员名单!$E:$E,人员名单!$B:$B) -> #N/A | ... AG51: =_xlfn.XLOOKUP(AG50,人员名单!$E:$E,人员名单!$B:$B) -> #N/A | AJ51: =_xlfn.XLOOKUP(AJ50,人员名单!$E:$E,人员名单!$B:$B) -> #N/A | AK51: =_xlfn.XLOOKUP(AK50,人员名单!$E:$E,人员名单!$B:$B) -> #N/A | AL51: =_xlfn.XLOOKUP(AL50,人员名单!$E:$E,人员名单!$B:$B) -> #N/A | AM51: =_xlfn.XLOOKUP(AM50,人员名单!$E:$E,人员名单!$B:$B) -> #N/A | AN51: =_xlfn.XLOOKUP(AN50,人员名单!$E:$E,人员名单!$B:$B) -> #N/A | AO51: =_xlfn.XLOOKUP(AO50,人员名单!$E:$E,人员名单!$B:$B) -> #N/A | AP51: =_xlfn.XLOOKUP(AP50,人员名单!$E:$E,人员名单!$B:$B) -> #N/A | AQ51: 分论坛七 | AR51: =_xlfn.XLOOKUP(AR50,人员名单!$E:$E,人员名单!$B:$B) -> #N/A | AS51: 分论坛七
A53: 第10排 | F53: 36 | G53: 35 | H53: 34 | I53: 33 | J53: 32 | K53: 31 | L53: 30 | M53: 29 | N53: 28 | Q53: 27 | R53: 26 | S53: 25 | T53: 24 | U53: 23 | V53: 22 | W53: 21 | X53: 20 | Y53: 19 | Z53: 18 | AA53: 17 | AB53: 16 | AC53: 15 | AD53: 14 | AE53: 13 | AF53: 12 | AG53: 11 | AJ53: 10 | AK53: 9 | AL53: 8 | AM53: 7 | AN53: 6 | AO53: 5 | AP53: 4 | AQ53: 3 | AR53: 2 | AW53: 第10排 | AY53: 35
F54: 407 | G54: 405 | H54: 403 | I54: 401 | J54: 399 | K54: 397 | L54: 395 | M54: 393 | N54: 391 | Q54: 389 | R54: 387 | S54: 385 | T54: 383 | U54: 381 | V54: 379 | W54: 377 | X54: 375 | Y54: 373 | Z54: 374 | AA54: 376 | AB54: 378 | AC54: 380 | AD54: 382 | AE54: 384 | AF54: 386 | AG54: 388 | AJ54: 390 | AK54: 392 | AL54: 394 | AM54: 396 | AN54: 398 | AO54: 400 | AP54: 402 | AQ54: 404 | AR54: 406
...

Sheet Sheet3
